Workbook

Sheet Resumo Executivo
A1: Template de Business Case
A2: Resumo executivo e visão consolidada da viabilidade
J3: Métrica | K3: Ano 1 | L3: Ano 2 | M3: Ano 3 | N3: Ano 4 | O3: Ano 5
A4: Resumo Executivo | J4: Receita | K4: ='Projeção Receitas'!C20 -> 374400 | L4: ='Projeção Receitas'!D20 -> 813960 | M4: ='Projeção Receitas'!E20 -> 1571724 | N4: ='Projeção Receitas'!F20 -> 2718566.5 | O4: ='Projeção Receitas'!G20 -> 4129317
A5: Nome do projeto | B5: BusFlow | J5: OPEX | K5: ='Resumo Investimentos'!C11 -> 526911.6 | L5: ='Resumo Investimentos'!D11 -> 538057.18 | M5: ='Resumo Investimentos'!E11 -> 564960.04 | N5: ='Resumo Investimentos'!F11 -> 593208.04 | O5: ='Resumo Investimentos'!G11 -> 622868.44
J6: CAPEX | K6: ='Resumo Investimentos'!C10 -> 0 | L6: ='Resumo Investimentos'!D10 -> 0 | M6: ='Resumo Investimentos'!E10 -> 34144.149 | N6: ='Resumo Investimentos'!F10 -> 0 | O6: ='Resumo Investimentos'!G10 -> 0
A7: Breve descritivo | B7: Automação Inteligente de Despacho de Frota de Ônibus via Machine Learning e Dados Climáticos | J7: Fluxo Líquido | K7: ='Fluxo de Caixa'!C12 -> -152511.6 | L7: ='Fluxo de Caixa'!D12 -> 275902.82 | M7: ='Fluxo de Caixa'!E12 -> 972619.81 | N7: ='Fluxo de Caixa'!F12 -> 2125358.5 | O7: ='Fluxo de Caixa'!G12 -> 3506448.5
A10: Objetivo principal do produto / serviço | B10: Otimizar a eficiência operacional do transporte público rodoviário e reduzir o tempo de espera dos passageiros em períodos de intempéries climáticas na cidade de São Paulo, por meio de um modelo preditivo de suporte à tomada de decisão para o CCO.
A13: Contexto do mercado e justificativa | B13: Atende passageiros e operadores de ônibus de São Paulo, diante dos atuais gargalos de mobilidade e impactos climáticos. Agir agora permite otimizar a operação e reduzir atrasos por meio de decisões mais rápidas e inteligentes.
A16: Principais benefícios esperados | B16: Ex.: receita incremental, redução de custos, ganho de produtividade e prazo para captura do benefício.
A20: Visão Financeira Consolidada
A22: Investimento total (CAPEX) | C22: OPEX total - 5 anos | E22: Receita total - 5 anos | G22: VPL
A23: ='Resumo Investimentos'!H10 -> 63639.149 | C23: ='Resumo Investimentos'!H11 -> 3203797.3 | E23: ='Projeção Receitas'!G21 -> 9607967.5 | G23: =Indicadores!B6 -> 3729138.4
A25: TIR | C25: ROI | E25: MOIC | G25: Payback
A26: =Indicadores!B7 -> 0.96136055 | C26: =Indicadores!B8 -> 1.9405216 | E26: =Indicadores!B9 -> 12.746105 | G26: =Indicadores!B10 -> 3
A47: Legenda: amarelo/azul = entrada editável | verde = link entre abas | preto = fórmula/cálculo.

Sheet Detalhes do Projeto
A1: Detalhes do Projeto
A2: Escopo, público, modelo de negócio, premissas e benchmarks
A4: Escopo (WBS)
A5: WBS | B5: Pacote de trabalho | C5: Entrega / Feature | D5: Descrição | E5: Responsável | F5: Início | G5: Fim | H5: Dependência | I5: Custo estimado (R$) | J5: Observações
A6: 1.1 | B6: Levantamento | C6: Requisitos | D6: Levantamento dos requisitos e necessidades da operação. | E6: Todos da equipe | F6: 46266 | G6: 46270 | H6: - | I6: 6096.24 | J6: Levantamento inicial e especificações (2% do esforço da equipe dev)
A7: 1.2 | B7: Dados | C7: Coleta e tratamento | D7: Integração e preparação dos dados de transporte e clima. | E7: Backend / Dados | F7: 46271 | G7: 46280 | H7: 1.1 | I7: 36577.44 | J7: Coleta, pipeline e tratamento de dados de transporte e clima (12% do esforço)
A8: 1.3 | B8: Banco de Dados | C8: Modelagem | D8: Modelagem e implementação do banco de dados. | E8: Backend | F8: 46275 | G8: 46283 | H8: 1.1 | I8: 24384.96 | J8: Modelagem relacional e estruturação do banco de dados (8% do esforço)
A9: 1.4 | B9: Machine Learning | C9: Modelo preditivo | D9: Desenvolvimento do modelo para previsão de demanda. | E9: Dados / ML | F9: 46281 | G9: 46295 | H9: 1.2 | I9: 67058.64 | J9: Engenharia de features, treino e validação do modelo preditivo de ML (22% do esforço)
A10: 1.5 | B10: Backend | C10: API | D10: Desenvolvimento da API para disponibilizar previsões e alertas. | E10: Backend | F10: 46290 | G10: 46303 | H10: 1.3, 1.4 | I10: 54866.16 | J10: Desenvolvimento das APIs RESTful de integração e despacho (18% do esforço)
A11: 1.6 | B11: Alertas | C11: Sistema de alertas | D11: Identificação de possíveis gargalos e geração de alertas operacionais. | E11: Backend / ML | F11: 46296 | G11: 46307 | H11: 1.4, 1.5 | I11: 30481.2 | J11: Motor de regras e sistema de alertas para o CCO (10% do esforço)
A12: 1.7 | B12: Dashboard | C12: Monitoramento | D12: Desenvolvimento de dashboard para visualização dos indicadores. | E12: Frontend / Dados | F12: 46303 | G12: 46315 | H12: 1.5 | I12: 36577.44 | J12: Dashboard analítico e interface visual operacional (12% do esforço)
A13: 1.8 | B13: Integração | C13: Integração dos módulos | D13: Integração entre banco, ML, API e dashboard. | E13: Todos da equipe | F13: 46313 | G13: 46320 | H13: 1.5, 1.6, 1.7 | I13: 18288.72 | J13: Integração ponta a ponta de todos os módulos (6% do esforço)
A14: 1.9 | B14: Testes | C14: Testes e validação | D14: Testes funcionais, integração e avaliação das previsões. | E14: Todos da equipe | F14: 46321 | G14: 46331 | H14: 1.8 | I14: 15240.6 | J14: Testes funcionais, testes de carga e homologação técnica (5% do esforço)
A15: 1.10 | B15: Implantação | C15: MVP BusFlow | D15: Disponibilização do protótipo funcional e documentação. | E15: Todos da equipe | F15: 46393 | G15: 46424 | H15: 1.9 | I15: 15240.6 | J15: Deploy do MVP em ambiente de produção e documentação final (5% do esforço)
A16: 1.11 | B16: Sustentação | C16: Correção de Erros | D16: Correção de erros encontrados em produção. | E16: Sustentação | F16: 46393 | G16: 48167 | H16: 1.10 | I16: 35000 | J16: Entrega final do projeto
A17: 1.12 | B17: Suporte | C17: Atendimento/ Acompanhamento | D17: Atendimento para auxilio da utilização da aplicação para o cliente. | E17: Suporte | F17: 46393 | G17: 48167 | H17: 1.10 | I17: 15000 | J17: Entrega final do projeto
A19: Público-alvo e Mercado Potencial
A20: Segmento | B20: Tipo | C20: Base potencial (clientes) | D20: % Endereçável | E20: TAM (clientes) | F20: SAM (clientes)
A21: Empresas/concessionárias de transporte coletivo | B21: Principal | C21: 1800 | D21: 1 | E21: 1800 | F21: 100
A22: Órgãos públicos de mobilidade urbana | B22: Secundário | C22: 5570 | D22: 1 | E22: 5570 | F22: 50
A23: Operadores de transporte municipal | B23: Secundário | C23: 500 | D23: 1 | E23: 500 | F23: 50
A24: Empresas de tecnologia para mobilidade | B24: Secundário | C24: 1000 | D24: 1 | E24: 1000 | F24: 100
A26: Modelo de Negócio
A27: Modelo principal | B27: B2B | D27: SaaS por assinatura, cobrando mensalmente pelo uso da plataforma de previsão, monitoramento e geração de alertas operacionais.
D28: O valor pode variar conforme o número de veículos, linhas monitoradas e funcionalidades contratadas.
A30: Premissas Utilizadas
A31: Premissa | B31: Valor | C31: Unidade | D31: Fonte / justificativa | E31: Sensibilidade
A32: TMA / taxa de desconto | B32: 0.12 | C32: % a.a. | D32: Definir conforme custo de capital / política da empresa | E32: Alta
A33: Alíquota de impostos sobre resultado | B33: 0 | C33: % | D33: Preencher conforme contexto do projeto | E33: Média
A34: Inflação / reajuste de custos | B34: 0.05 | C34: % a.a. | D34: Premissa macroeconômica | E34: Média
A35: Horizonte de análise | B35: 5 | C35: anos | D35: Padrão do exercício | E35: Baixa
A36: Reserva de contingência | B36: 0.1 | C36: % CAPEX | D36: Conforme maturidade do escopo | E36: Média
A38: Benchmarks e Referências
A39: Benchmark / Concorrente | B39: Proposta de valor | C39: Preço / Modelo | D39: Principais diferenciais | E39: Lacunas percebidas | F39: Fonte / URL
A40: Optibus | B40: Plataforma completa para planejamento, escalonamento e operação de transporte público. Utiliza otimização, ML e IA para adaptar a operação à demanda. | C40: Comercial / sob consulta | D40: IA, ML, otimização de frota e motoristas, ajustes em tempo real e plataforma Cloud. | E40: Solução muito ampla; não é focada especificamente em correlacionar dados climáticos + demanda para recomendar despacho. | F40: https://optibus.com/product/?new_lang=em
A41: INIT – MOBILE-ITCS | B41: Controle operacional em tempo real, monitoramento da frota, despacho, gestão de incidentes e informação ao passageiro. | C41: Comercial / sob consulta | D41: Forte integração com CCO, AVL, controle de frota, incidentes e informações em tempo real. Também possui IA para previsão de chegada. | E41: Foco maior em monitoramento e controle em tempo real; a proposta do BusFlow enfatiza previsão de demanda influenciada por clima para antecipar decisões de despacho. | F41: https://www.initse.com/enus/solutions/operations-control-real-time-passenger-information/?
A42: SISCOG | B42: Otimização de recursos e apoio à decisão para transporte público, incluindo planejamento, veículos e despacho em tempo real. | C42: Comercial / sob consulta | D42: Combinação de IA + Pesquisa Operacional, otimização de recursos, cenários "what-if" e replanejamento. | E42: Forte atuação em ferrovias e metrôs; solução mais voltada à otimização abrangente de recursos do que a um MVP específico de previsão de demanda de ônibus baseada em clima. | F42: https://www.siscog.com/en-us/

Sheet Resumo Investimentos
A1: Resumo dos Investimentos
A2: CAPEX, OPEX e evolução dos custos ao longo do horizonte
A4: Resumo por Classificação
A5: Classificação | B5: Ano 0 | C5: Ano 1 | D5: Ano 2 | E5: Ano 3 | F5: Ano 4 | G5: Ano 5 | H5: Total
A6: CAPEX | B6: =B10 -> 29495 | C6: =C10 -> 0 | D6: =D10 -> 0 | E6: =E10 -> 34144.149 | F6: =F10 -> 0 | G6: =G10 -> 0 | H6: =SUM(B6:G6) -> 63639.149
A7: OPEX (excl. depreciação) | B7: =B11 -> 357792 | C7: =C11 -> 526911.6 | D7: =D11 -> 538057.18 | E7: =E11 -> 564960.04 | F7: =F11 -> 593208.04 | G7: =G11 -> 622868.44 | H7: =SUM(B7:G7) -> 3203797.3
A8: Pessoal | B8: =SUMIF($C$15:$C$28,"Pessoal",G$15:G$28) -> 304812 | C8: =SUMIF($C$15:$C$28,"Pessoal",H$15:H$28) -> 406332.6 | D8: =SUMIF($C$15:$C$28,"Pessoal",I$15:I$28) -> 426649.23 | E8: =SUMIF($C$15:$C$28,"Pessoal",J$15:J$28) -> 447981.69 | F8: =SUMIF($C$15:$C$28,"Pessoal",K$15:K$28) -> 470380.78 | G8: =SUMIF($C$15:$C$28,"Pessoal",L$15:L$28) -> 493899.81 | H8: =SUM(B8:G8) -> 2550056.1
A9: Serviços / Sustentação | B9: =SUMIF($C$15:$C$28,"Serviços / Sustentação",G$15:G$28) -> 0 | C9: =SUMIF($C$15:$C$28,"Serviços / Sustentação",H$15:H$28) -> 0 | D9: =SUMIF($C$15:$C$28,"Serviços / Sustentação",I$15:I$28) -> 0 | E9: =SUMIF($C$15:$C$28,"Serviços / Sustentação",J$15:J$28) -> 0 | F9: =SUMIF($C$15:$C$28,"Serviços / Sustentação",K$15:K$28) -> 0 | G9: =SUMIF($C$15:$C$28,"Serviços / Sustentação",L$15:L$28) -> 0 | H9: =SUM(B9:G9) -> 0
A10: Total CAPEX | B10: =SUMIF($B$15:$B$28,"CAPEX",G$15:G$28) -> 29495 | C10: =SUMIF($B$15:$B$28,"CAPEX",H$15:H$28) -> 0 | D10: =SUMIF($B$15:$B$28,"CAPEX",I$15:I$28) -> 0 | E10: =SUMIF($B$15:$B$28,"CAPEX",J$15:J$28) -> 34144.149 | F10: =SUMIF($B$15:$B$28,"CAPEX",K$15:K$28) -> 0 | G10: =SUMIF($B$15:$B$28,"CAPEX",L$15:L$28) -> 0 | H10: =SUM(B10:G10) -> 63639.149
A11: Total OPEX (caixa) | B11: =SUMIFS(G$15:G$28,$B$15:$B$28,"OPEX",$C$15:$C$28,"<>Depreciação") -> 357792 | C11: =SUMIFS(H$15:H$28,$B$15:$B$28,"OPEX",$C$15:$C$28,"<>Depreciação") -> 526911.6 | D11: =SUMIFS(I$15:I$28,$B$15:$B$28,"OPEX",$C$15:$C$28,"<>Depreciação") -> 538057.18 | E11: =SUMIFS(J$15:J$28,$B$15:$B$28,"OPEX",$C$15:$C$28,"<>Depreciação") -> 564960.04 | F11: =SUMIFS(K$15:K$28,$B$15:$B$28,"OPEX",$C$15:$C$28,"<>Depreciação") -> 593208.04 | G11: =SUMIFS(L$15:L$28,$B$15:$B$28,"OPEX",$C$15:$C$28,"<>Depreciação") -> 622868.44 | H11: =SUM(B11:G11) -> 3203797.3
A13: Detalhamento de Investimentos e Custos
A14: Item | B14: CAPEX / OPEX | C14: Categoria | D14: Compra / Aluguel | E14: Unidade | F14: Qtd. | G14: Ano 0 | H14: Ano 1 | I14: Ano 2 | J14: Ano 3 | K14: Ano 4 | L14: Ano 5
A15: Equipe de desenvolvimento/UX/DevOps | B15: OPEX | C15: Pessoal | D15: Serviço | E15: HC | F15: 3 | G15: 304812 | H15: =G15*1.05 -> 320052.6 | I15: =H15*1.05 -> 336055.23 | J15: =I15*1.05 -> 352857.99 | K15: =J15*1.05 -> 370500.89 | L15: =K15*1.05 -> 389025.94
A16: Treinamento / Capacitação | B16: OPEX | C16: Serviço | D16: Compra | E16: Pacote | F16: 2 | G16: 0 | H16: 4000 | I16: 1600 | J16: =I16*1.05 -> 1680 | K16: =J16*1.05 -> 1764 | L16: =K16*1.05 -> 1852.2
A17: Notebooks / Hardware | B17: CAPEX | C17: Hardware | D17: Compra | E17: Un. | F17: 5 | G17: 29495 | H17: 0 | I17: 0 | J17: =G17*(1+'Detalhes do Projeto'!$B$34)^3 -> 34144.149 | K17: 0 | L17: 0
A18: Cloud / Infraestrutura AWS | B18: OPEX | C18: Serviço | D18: Aluguel | E18: Mês | F18: 12 | G18: 44640 | H18: =G18*1.05 -> 46872 | I18: =H18*1.05 -> 49215.6 | J18: =I18*1.05 -> 51676.38 | K18: =J18*1.05 -> 54260.199 | L18: =K18*1.05 -> 56973.209
A19: Claude / API de IA | B19: OPEX | C19: Serviço | D19: Uso / API | E19: Ano | F19: 3 | G19: 3300 | H19: =G19*1.05 -> 3465 | I19: =H19*1.05 -> 3638.25 | J19: =I19*1.05 -> 3820.1625 | K19: =J19*1.05 -> 4011.1706 | L19: =K19*1.05 -> 4211.7292
A20: Configuração do Dominio | B20: OPEX | C20: Serviço | D20: Serviço | E20: Ano | F20: 1 | G20: 40 | H20: =G20*1.05 -> 42 | I20: =H20*1.05 -> 44.1 | J20: =I20*1.05 -> 46.305 | K20: =J20*1.05 -> 48.62025 | L20: =K20*1.05 -> 51.051263
A21: Go-To-Market / Vendas B2B (Lançamento) | B21: OPEX | C21: Serviço | D21: Serviço | E21: Campanha | F21: 1 | G21: 0 | H21: 12000 | I21: 0 | J21: 0 | K21: 0 | L21: 0
A22: Go-To-Market / Vendas B2B (Recorrente) | B22: OPEX | C22: Serviço | D22: Serviço | E22: Mês | F22: 12 | G22: 0 | H22: =3000*12 -> 36000 | I22: =H22*1.05 -> 37800 | J22: =I22*1.05 -> 39690 | K22: =J22*1.05 -> 41674.5 | L22: =K22*1.05 -> 43758.225
A23: Suporte / Sustentação | B23: OPEX | C23: Pessoal | D23: Serviço | E23: HC | F23: 2 | G23: 0 | H23: 86280 | I23: =H23*1.05 -> 90594 | J23: =I23*1.05 -> 95123.7 | K23: =J23*1.05 -> 99879.885 | L23: =K23*1.05 -> 104873.88
A24: Monitoramento e Observabilidade (SaaS) | B24: OPEX | C24: Serviço | D24: Serviço | E24: Mês | F24: 12 | G24: 0 | H24: =1000*12 -> 12000 | I24: =H24*1.05 -> 12600 | J24: =I24*1.05 -> 13230 | K24: =J24*1.05 -> 13891.5 | L24: =K24*1.05 -> 14586.075
A25: Contabilidade | B25: OPEX | C25: Serviço | D25: Serviço | E25: Mês | F25: 1 | G25: 0 | H25: =350*12 -> 4200 | I25: =H25*1.05 -> 4410 | J25: =I25*1.05 -> 4630.5 | K25: =J25*1.05 -> 4862.025 | L25: =K25*1.05 -> 5105.1263
A26: Impostos / Taxas operacionais | B26: OPEX | C26: Impostos | D26: Taxa | E26: Mês | F26: 1 | G26: 0 | H26: 0 | I26: 0 | J26: 0 | K26: 0 | L26: 0
A27: Contingência | B27: OPEX | C27: Contingência | D27: Reserva | E27: Projeto | F27: 1 | G27: 5000 | H27: 2000 | I27: =H27*1.05 -> 2100 | J27: =I27*1.05 -> 2205 | K27: =J27*1.05 -> 2315.25 | L27: =K27*1.05 -> 2431.0125
A28: TOTAL ESTIMADO | B28: — | C28: — | D28: — | E28: — | F28: — | G28: =SUM(G15:G27) -> 387287 | H28: =SUM(H15:H27) -> 526911.6 | I28: =SUM(I15:I27) -> 538057.18 | J28: =SUM(J15:J27) -> 599104.19 | K28: =SUM(K15:K27) -> 593208.04 | L28: =SUM(L15:L27) -> 622868.44
A29: Nota: depreciação apoia a visão contábil, mas é item não-caixa. A análise econômica deve considerar o Fluxo de Caixa.
A33: Item | B33: Compra / Aluguel | C33: Qtd. | D33: Ano 0 | E33: Individual | F33: Explicação
A34: Equipe de desenvolvimento/UX/DevOps | B34: Serviço | C34: 3 | D34: 304812 | E34: 8466.52 | F34: Remuneração de 3 desenvolvedores plenos no Ano 0 totalizando R$ 304.812,00 (R$ 8.466,52/mês por dev), com reajuste anual de 5% conforme inflação.
A35: Treinamento / Capacitação | B35: Compra | C35: 2 | D35: 0 | E35: 2000 | F35: Baseado em pesquisas, estimativa média de R$ 2.000 para treinamentos e capacitações da equipe no primeiro ano. Nos anos seguintes, foi considerada uma necessidade menor, de R$ 800,00 anuais.
A36: Notebooks / Hardware | B36: Compra | C36: 5 | D36: =C36*E36 -> 29495 | E36: 5899 | F36: Aquisição de 5 notebooks corporativos (R$ 5.899/unidade) no Ano 0. Substituição integral no Ano 3 corrigida pela inflação composta de 5% a.a. em 3 anos (fator 1,1576 = R$ 34.144,38).
A37: Cloud / Infraestrutura AWS | B37: Aluguel | C37: 12 | D37: =E37*12 -> 44640 | E37: 3720 | F37: Estimativa de R$ 3.720,00 mensais para infraestrutura e banco na AWS (R$ 44.640,00/ano), com reajuste anual de 5% nos anos seguintes.
A38: Claude / API de IA | B38: Uso / API | C38: 3 | D38: =E38*C38 -> 3300 | E38: 1100 | F38: Licenças de API de IA (Claude/LLM) estimadas em R$ 1.100,00/ano por desenvolvedor (3 licenças = R$ 3.300,00/ano), reajustadas a 5% a.a.
A39: Configuração do Dominio | B39: Serviço | C39: 1 | D39: 40 | E39: 40 | F39: Anuidade de registro de domínio e DNS (Registro.br / Route53), classificada como despesa operacional (OPEX), reajustada a 5% a.a.
A40: Go-To-Market / Vendas B2B (Lançamento) | B40: Serviço | C40: 1 | D40: 12000 | E40: 12000 | F40: Verba inicial de Go-To-Market B2B no Ano 1 para estruturação de materiais de vendas técnicas, landing page institucional e setup de prospecção comercial.
A41: Go-To-Market / Vendas B2B (Recorrente) | B41: Serviço | C41: 12 | D41: 0 | E41: 3000 | F41: Verba comercial recorrente de R$ 3.000,00/mês (R$ 36.000,00/ano) para assessoria de prospecção ativa outbound B2B e participação em eventos de mobilidade (ex: NTU/ANTP), com reajuste de 5% a.a.
A42: Suporte / Sustentação | B42: Serviço | C42: 2 | D42: - | E42: 3595 | F42: Valor baseado na pesquisa do estado de são paulo considerando 2 analistas de suporte a nível pleno, com o ajuste por inflação de 5% (dado variação fica no intervalo de 4% a 6%).
A43: Monitoramento e Observabilidade (SaaS) | B43: Assinatura SaaS | C43: 12 | E43: 1000 | F43: Assinatura de ferramentas SaaS gerenciadas de observabilidade (AWS CloudWatch, Grafana Cloud Pro, Sentry) orçada em R$ 1.000,00/mês (R$ 12.000,00/ano), operadas pela equipe dev com reajuste de 5% a.a.
A44: Contabilidade | B44: Serviço | C44: 1 | D44: 0 | E44: 350 | F44: Baseado em pesquisas, estamos considerando uma assinatura de um serviço de contabilidade.
A45: Impostos / Taxas operacionais | B45: Taxa | C45: 1 | D45: 0 | E45: 0 | F45: Consideramos 15% do faturamento de taxa de um CNPJ Simples.
...

Sheet Projeção Receitas
A1: Projeção de Receitas
A2: Clientes, adoção, ticket, churn e investimentos de aquisição
A4: Premissas e Projeção - 5 anos
A5: Métrica | B5: Unidade | C5: Ano 1 | D5: Ano 2 | E5: Ano 3 | F5: Ano 4 | G5: Ano 5
A6: Base inicial de clientes / usuários | B6: clientes | C6: 1 | D6: =SUM(C6:C7) -> 4 | E6: =SUM(D6:D7) -> 8 | F6: =SUM(E6:E7) -> 14 | G6: =SUM(F6:F7) -> 22
A7: Novos clientes / usuários | B7: clientes | C7: 3 | D7: 4 | E7: 6 | F7: 8 | G7: 10
A8: Crescimento de novos clientes | B8: % a.a. | C8: 0 | D8: =(D7-C7)/C7 -> 0.33333333 | E8: =(E7-D7)/D7 -> 0.5 | F8: =(F7-E7)/E7 -> 0.33333333 | G8: =(G7-F7)/F7 -> 0.25
A9: Churn | B9: % a.a. | C9: 0.1 | D9: 0.1 | E9: 0.1 | F9: 0.1 | G9: 0.1
A10: Clientes ativos ao fim do ano | B10: clientes | C10: =C6*(1-C9)+C7 -> 3.9 | D10: =D6*(1-D9)+D7 -> 7.6 | E10: =E6*(1-E9)+E7 -> 13.2 | F10: =F6*(1-F9)+F7 -> 20.6 | G10: =G6*(1-G9)+G7 -> 29.8
A11: Curva de adoção / MAU | B11: % ativos | C11: 0.8 | D11: 0.85 | E11: 0.9 | F11: 0.95 | G11: 0.95
A12: MAU médio estimado | B12: usuários | C12: =C10*C11 -> 3.12 | D12: =D10*D11 -> 6.46 | E12: =E10*E11 -> 11.88 | F12: =F10*F11 -> 19.57 | G12: =G10*G11 -> 28.31
A13: Ticket médio / ASP | B13: R$ / mês | C13: 10000 | D13: 10500 | E13: 11025 | F13: 11576.25 | G13: 12155.06
A14: Sazonalidade | B14: fator | C14: 1 | D14: 1 | E14: 1 | F14: 1 | G14: 1
A15: Receita bruta projetada | B15: R$ / ano | C15: =C12*C13*12*C14 -> 374400 | D15: =D12*D13*12*D14 -> 813960 | E15: =E12*E13*12*E14 -> 1571724 | F15: =F12*F13*12*F14 -> 2718566.5 | G15: =G12*G13*12*G14 -> 4129317
A16: Marketing / mídia | B16: R$ / ano | C16: =SUM('Resumo Investimentos'!H21:H22) -> 48000 | D16: =SUM('Resumo Investimentos'!I21:I22) -> 37800 | E16: =SUM('Resumo Investimentos'!J21:J22) -> 39690 | F16: =SUM('Resumo Investimentos'!K21:K22) -> 41674.5 | G16: =SUM('Resumo Investimentos'!L21:L22) -> 43758.225
A17: CAC | B17: R$ / novo cliente | C17: =IF(C7=0,0,C16/C7) -> 16000 | D17: =IF(D7=0,0,D16/D7) -> 9450 | E17: =IF(E7=0,0,E16/E7) -> 6615 | F17: =IF(F7=0,0,F16/F7) -> 5209.3125 | G17: =IF(G7=0,0,G16/G7) -> 4375.8225
A19: Resumo de Receita
A20: Receita projetada | B20: R$ / ano | C20: =C15 -> 374400 | D20: =D15 -> 813960 | E20: =E15 -> 1571724 | F20: =F15 -> 2718566.5 | G20: =G15 -> 4129317
A21: Receita total - 5 anos | G21: =SUM(C20:G20) -> 9607967.5

Sheet Fluxo de Caixa
A1: Fluxo de Caixa Projetado
A2: Fluxo econômico do projeto: investimento, operação, geração de caixa e payback
A4: Fluxo de Caixa - Ano 0 a Ano 5
A5: Linha | B5: Ano 0 | C5: Ano 1 | D5: Ano 2 | E5: Ano 3 | F5: Ano 4 | G5: Ano 5
A6: Receita anual esperada | B6: 0 | C6: ='Projeção Receitas'!C20 -> 374400 | D6: ='Projeção Receitas'!D20 -> 813960 | E6: ='Projeção Receitas'!E20 -> 1571724 | F6: ='Projeção Receitas'!F20 -> 2718566.5 | G6: ='Projeção Receitas'!G20 -> 4129317
A7: Custo operacional anualizado (OPEX) | B7: ='Resumo Investimentos'!B11 -> 357792 | C7: ='Resumo Investimentos'!C11 -> 526911.6 | D7: ='Resumo Investimentos'!D11 -> 538057.18 | E7: ='Resumo Investimentos'!E11 -> 564960.04 | F7: ='Resumo Investimentos'!F11 -> 593208.04 | G7: ='Resumo Investimentos'!G11 -> 622868.44
A8: EBITDA / Resultado operacional | B8: =B6-B7 -> -357792 | C8: =C6-C7 -> -152511.6 | D8: =D6-D7 -> 275902.82 | E8: =E6-E7 -> 1006764 | F8: =F6-F7 -> 2125358.5 | G8: =G6-G7 -> 3506448.5
A9: Impostos sobre resultado | B9: =IF((B8-B11)>0,(B8-B11)*'Detalhes do Projeto'!$B$33,0) -> 0 | C9: =IF((C8-C11)>0,(C8-C11)*'Detalhes do Projeto'!$B$33,0) -> 0 | D9: =IF((D8-D11)>0,(D8-D11)*'Detalhes do Projeto'!$B$33,0) -> 0 | E9: =IF((E8-E11)>0,(E8-E11)*'Detalhes do Projeto'!$B$33,0) -> 0 | F9: =IF((F8-F11)>0,(F8-F11)*'Detalhes do Projeto'!$B$33,0) -> 0 | G9: =IF((G8-G11)>0,(G8-G11)*'Detalhes do Projeto'!$B$33,0) -> 0
A10: CAPEX | B10: ='Resumo Investimentos'!B10 -> 29495 | C10: ='Resumo Investimentos'!C10 -> 0 | D10: ='Resumo Investimentos'!D10 -> 0 | E10: ='Resumo Investimentos'!E10 -> 34144.149 | F10: ='Resumo Investimentos'!F10 -> 0 | G10: ='Resumo Investimentos'!G10 -> 0
A11: Depreciação (não caixa) | B11: =SUMIF('Resumo Investimentos'!$C$15:$C$28,"Depreciação",'Resumo Investimentos'!$G$15:$G$28) -> 0 | C11: =SUMIF('Resumo Investimentos'!$C$15:$C$28,"Depreciação",'Resumo Investimentos'!$H$15:$H$28) -> 0 | D11: =SUMIF('Resumo Investimentos'!$C$15:$C$28,"Depreciação",'Resumo Investimentos'!$I$15:$I$28) -> 0 | E11: =SUMIF('Resumo Investimentos'!$C$15:$C$28,"Depreciação",'Resumo Investimentos'!$J$15:$J$28) -> 0 | F11: =SUMIF('Resumo Investimentos'!$C$15:$C$28,"Depreciação",'Resumo Investimentos'!$K$15:$K$28) -> 0 | G11: =SUMIF('Resumo Investimentos'!$C$15:$C$28,"Depreciação",'Resumo Investimentos'!$L$15:$L$28) -> 0
A12: Fluxo líquido | B12: =B6-B7-B9-B10 -> -387287 | C12: =C6-C7-C9-C10 -> -152511.6 | D12: =D6-D7-D9-D10 -> 275902.82 | E12: =E6-E7-E9-E10 -> 972619.81 | F12: =F6-F7-F9-F10 -> 2125358.5 | G12: =G6-G7-G9-G10 -> 3506448.5
A13: Fluxo acumulado | B13: =B12 -> -387287 | C13: =B13+C12 -> -539798.6 | D13: =C13+D12 -> -263895.78 | E13: =D13+E12 -> 708724.03 | F13: =E13+F12 -> 2834082.5 | G13: =F13+G12 -> 6340531.1
A15: Payback
A16: Payback estimado (anos) | B16: =IF(B13>=0,0,IF(C13>=0,1,IF(D13>=0,2,IF(E13>=0,3,IF(F13>=0,4,IF(G13>=0,5,6)))))) -> 3 | D16: Status | E16: =IF(B16<=5,"Payback dentro do horizonte","Payback > 5 anos") -> Payback dentro do horizonte

Sheet Indicadores
A1: Indicadores de Viabilidade
A2: Métricas para decisão de investimento
A4: Indicadores
A5: Indicador | B5: Resultado | C5: Interpretação / Critério | E5: TMA | F5: ='Detalhes do Projeto'!B32 -> 0.12
A6: VPL | B6: {='Fluxo de Caixa'!B12+NPV(F5,'Fluxo de Caixa'!C12:G12)} -> 3729138.4 | C6: VPL > 0 indica criação de valor à taxa de desconto adotada.
A7: TIR | B7: =IF(MIN('Fluxo de Caixa'!B12:G12)<0,IF(MAX('Fluxo de Caixa'!B12:G12)>0,IRR('Fluxo de Caixa'!B12:G12),0),0) -> 0.96136055 | C7: TIR > TMA indica retorno acima da taxa mínima exigida.
A8: ROI | B8: =IF((SUM('Resumo Investimentos'!B10:G10)+SUM('Resumo Investimentos'!B11:G11))=0,0,(SUM('Projeção Receitas'!C20:G20)-SUM('Resumo Investimentos'!B10:G10)-SUM('Resumo Investimentos'!B11:G11)-SUM('Fluxo de Caixa'!B9:G9))/(SUM('Resumo Investimentos'!B10:G10)+SUM('Resumo Investimentos'!B11:G11))) -> 1.9405216 | C8: ROI > 0 indica retorno líquido positivo sobre o investimento.
A9: MOIC | B9: =IF(ABS(SUMIF('Fluxo de Caixa'!B12:G12,"<0",'Fluxo de Caixa'!B12:G12))=0,0,SUMIF('Fluxo de Caixa'!B12:G12,">0",'Fluxo de Caixa'!B12:G12)/ABS(SUMIF('Fluxo de Caixa'!B12:G12,"<0",'Fluxo de Caixa'!B12:G12))) -> 12.746105 | C9: MOIC > 1,0x indica retorno bruto superior ao capital investido.
A10: Payback | B10: ='Fluxo de Caixa'!B16 -> 3 | C10: Quanto menor, mais cedo o investimento é recuperado.
A13: Leitura Integrada
A14: Sinalização automática | B14: =IF(AND(B6>0,B7>F5,B10<=5),"VIÁVEL - validar riscos e premissas",IF(AND(B6>=0,B7>=F5),"LIMÍTROFE - revisar premissas","REVISAR - indicadores não sustentam a aprovação")) -> VIÁVEL - validar riscos e premissas

Sheet Análise de Riscos
A1: Análise de Riscos
A2: Registro e priorização dos principais riscos do Business Case
A4: Risk Register
A5: ID | B5: Risco | C5: Categoria | D5: Prob. (1-5) | E5: Impacto (1-5) | F5: Score | G5: Nível | H5: Impacto financeiro (R$) | I5: Mitigação | J5: Responsável | K5: Status
A6: R01 | F6: =D6*E6 -> 0 | G6: =IF(F6>=15,"Alto",IF(F6>=8,"Médio","Baixo")) -> Baixo
A7: R02 | F7: =D7*E7 -> 0 | G7: =IF(F7>=15,"Alto",IF(F7>=8,"Médio","Baixo")) -> Baixo
A8: R03 | F8: =D8*E8 -> 0 | G8: =IF(F8>=15,"Alto",IF(F8>=8,"Médio","Baixo")) -> Baixo
A9: R04 | F9: =D9*E9 -> 0 | G9: =IF(F9>=15,"Alto",IF(F9>=8,"Médio","Baixo")) -> Baixo
A10: R05 | F10: =D10*E10 -> 0 | G10: =IF(F10>=15,"Alto",IF(F10>=8,"Médio","Baixo")) -> Baixo
A11: R06 | F11: =D11*E11 -> 0 | G11: =IF(F11>=15,"Alto",IF(F11>=8,"Médio","Baixo")) -> Baixo
A12: R07 | F12: =D12*E12 -> 0 | G12: =IF(F12>=15,"Alto",IF(F12>=8,"Médio","Baixo")) -> Baixo
A13: R08 | F13: =D13*E13 -> 0 | G13: =IF(F13>=15,"Alto",IF(F13>=8,"Médio","Baixo")) -> Baixo
A14: R09 | F14: =D14*E14 -> 0 | G14: =IF(F14>=15,"Alto",IF(F14>=8,"Médio","Baixo")) -> Baixo
A15: R10 | F15: =D15*E15 -> 0 | G15: =IF(F15>=15,"Alto",IF(F15>=8,"Médio","Baixo")) -> Baixo
A16: R11 | F16: =D16*E16 -> 0 | G16: =IF(F16>=15,"Alto",IF(F16>=8,"Médio","Baixo")) -> Baixo
A17: R12 | F17: =D17*E17 -> 0 | G17: =IF(F17>=15,"Alto",IF(F17>=8,"Médio","Baixo")) -> Baixo
... A20: R15 | F20: =D20*E20 -> 0 | G20: =IF(F20>=15,"Alto",IF(F20>=8,"Médio","Baixo")) -> Baixo

Sheet Cenários
A1: Análise de Cenários
A2: Sensibilidade do Business Case a mudanças nas premissas
A4: Premissas dos Cenários
A5: Premissa | B5: Conservador | C5: Base | D5: Otimista
A6: Multiplicador de Receita | B6: 0.8 | C6: 1 | D6: 1.2
A7: Multiplicador de OPEX | B7: 1.1 | C7: 1 | D7: 0.95
A8: Multiplicador de CAPEX | B8: 1.1 | C8: 1 | D8: 1
A10: Resultados por Cenário
A11: Indicador | B11: Conservador | C11: Base | D11: Otimista
A12: Receita 5 anos | B12: ='Projeção Receitas'!G21*B$6 -> 7686374 | C12: ='Projeção Receitas'!G21*C$6 -> 9607967.5 | D12: ='Projeção Receitas'!G21*D$6 -> 11529561
A13: OPEX 5 anos | B13: ='Resumo Investimentos'!H11*B$7 -> 3524177 | C13: ='Resumo Investimentos'!H11*C$7 -> 3203797.3 | D13: ='Resumo Investimentos'!H11*D$7 -> 3043607.4
A14: CAPEX total | B14: ='Resumo Investimentos'!H10*B$8 -> 70003.064 | C14: ='Resumo Investimentos'!H10*C$8 -> 63639.149 | D14: ='Resumo Investimentos'!H10*D$8 -> 63639.149
A15: VPL | B15: =-('Resumo Investimentos'!B10*B$8)-('Resumo Investimentos'!B11*B$7)+((('Projeção Receitas'!C20*B$6)-('Resumo Investimentos'!C11*B$7)-('Resumo Investimentos'!C10*B$8))/(1+'Detalhes do Projeto'!$B$32)^1)+((('Projeção Receitas'!D20*B$6)-('Resumo Investimentos'!D11*B$7)-('Resumo Investimentos'!D10*B$8))/(1+'Detalhes do Projeto'!$B$32)^2)+((('Projeção Receitas'!E20*B$6)-('Resumo Investimentos'!E11*B$7)-('Resumo Investimentos'!E10*B$8))/(1+'Detalhes do Projeto'!$B$32)^3)+((('Projeção Receitas'!F20*B$6)-('Resumo Investimentos'!F11*B$7)-('Resumo Investimentos'!F10*B$8))/(1+'Detalhes do Projeto'!$B$32)^4)+((('Projeção Receitas'!G20*B$6)-('Resumo Investimentos'!G11*B$7)-('Resumo Investimentos'!G10*B$8))/(1+'Detalhes do Projeto'!$B$32)^5) -> 2250249.6 | C15: =-('Resumo Investimentos'!B10*C$8)-('Resumo Investimentos'!B11*C$7)+((('Projeção Receitas'!C20*C$6)-('Resumo Investimentos'!C11*C$7)-('Resumo Investimentos'!C10*C$8))/(1+'Detalhes do Projeto'!$B$32)^1)+((('Projeção Receitas'!D20*C$6)-('Resumo Investimentos'!D11*C$7)-('Resumo Investimentos'!D10*C$8))/(1+'Detalhes do Projeto'!$B$32)^2)+((('Projeção Receitas'!E20*C$6)-('Resumo Investimentos'!E11*C$7)-('Resumo Investimentos'!E10*C$8))/(1+'Detalhes do Projeto'!$B$32)^3)+((('Projeção Receitas'!F20*C$6)-('Resumo Investimentos'!F11*C$7)-('Resumo Investimentos'!F10*C$8))/(1+'Detalhes do Projeto'!$B$32)^4)+((('Projeção Receitas'!G20*C$6)-('Resumo Investimentos'!G11*C$7)-('Resumo Investimentos'!G10*C$8))/(1+'Detalhes do Projeto'!$B$32)^5) -> 3729138.4 | D15: =-('Resumo Investimentos'!B10*D$8)-('Resumo Investimentos'!B11*D$7)+((('Projeção Receitas'!C20*D$6)-('Resumo Investimentos'!C11*D$7)-('Resumo Investimentos'!C10*D$8))/(1+'Detalhes do Projeto'!$B$32)^1)+((('Projeção Receitas'!D20*D$6)-('Resumo Investimentos'!D11*D$7)-('Resumo Investimentos'!D10*D$8))/(1+'Detalhes do Projeto'!$B$32)^2)+((('Projeção Receitas'!E20*D$6)-('Resumo Investimentos'!E11*D$7)-('Resumo Investimentos'!E10*D$8))/(1+'Detalhes do Projeto'!$B$32)^3)+((('Projeção Receitas'!F20*D$6)-('Resumo Investimentos'!F11*D$7)-('Resumo Investimentos'!F10*D$8))/(1+'Detalhes do Projeto'!$B$32)^4)+((('Projeção Receitas'!G20*D$6)-('Resumo Investimentos'!G11*D$7)-('Resumo Investimentos'!G10*D$8))/(1+'Detalhes do Projeto'!$B$32)^5) -> 5083160.4
A16: ROI | B16: =IF((B13+B14)=0,0,(B12-B13-B14)/(B13+B14)) -> 1.1385612 | C16: =IF((C13+C14)=0,0,(C12-C13-C14)/(C13+C14)) -> 1.9405216 | D16: =IF((D13+D14)=0,0,(D12-D13-D14)/(D13+D14)) -> 2.7105394
A17: Payback | B17: =IF(B22>=0,0,IF(C22>=0,1,IF(D22>=0,2,IF(E22>=0,3,IF(F22>=0,4,IF(G22>=0,5,6)))))) -> 4 | C17: =IF(B24>=0,0,IF(C24>=0,1,IF(D24>=0,2,IF(E24>=0,3,IF(F24>=0,4,IF(G24>=0,5,6)))))) -> 3 | D17: =IF(B26>=0,0,IF(C26>=0,1,IF(D26>=0,2,IF(E26>=0,3,IF(F26>=0,4,IF(G26>=0,5,6)))))) -> 2
A19: Fluxo de Caixa Ajustado por Cenário
A20: Cenário / Fluxo | B20: Ano 0 | C20: Ano 1 | D20: Ano 2 | E20: Ano 3 | F20: Ano 4 | G20: Ano 5
A21: Conservador | B21: =-('Resumo Investimentos'!B10*B$8)-('Resumo Investimentos'!B11*B$7) -> -426015.7 | C21: =('Projeção Receitas'!C20*B$6)-('Resumo Investimentos'!C11*B$7)-('Resumo Investimentos'!C10*B$8) -> -280082.76 | D21: =('Projeção Receitas'!D20*B$6)-('Resumo Investimentos'!D11*B$7)-('Resumo Investimentos'!D10*B$8) -> 59305.102 | E21: =('Projeção Receitas'!E20*B$6)-('Resumo Investimentos'!E11*B$7)-('Resumo Investimentos'!E10*B$8) -> 598364.59 | F21: =('Projeção Receitas'!F20*B$6)-('Resumo Investimentos'!F11*B$7)-('Resumo Investimentos'!F10*B$8) -> 1522324.4 | G21: =('Projeção Receitas'!G20*B$6)-('Resumo Investimentos'!G11*B$7)-('Resumo Investimentos'!G10*B$8) -> 2618298.3
A22: Conservador - Acumulado | B22: =B21 -> -426015.7 | C22: =B22+C21 -> -706098.46 | D22: =C22+D21 -> -646793.36 | E22: =D22+E21 -> -48428.765 | F22: =E22+F21 -> 1473895.6 | G22: =F22+G21 -> 4092193.9
A23: Base | B23: =-('Resumo Investimentos'!B10*C$8)-('Resumo Investimentos'!B11*C$7) -> -387287 | C23: =('Projeção Receitas'!C20*C$6)-('Resumo Investimentos'!C11*C$7)-('Resumo Investimentos'!C10*C$8) -> -152511.6 | D23: =('Projeção Receitas'!D20*C$6)-('Resumo Investimentos'!D11*C$7)-('Resumo Investimentos'!D10*C$8) -> 275902.82 | E23: =('Projeção Receitas'!E20*C$6)-('Resumo Investimentos'!E11*C$7)-('Resumo Investimentos'!E10*C$8) -> 972619.81 | F23: =('Projeção Receitas'!F20*C$6)-('Resumo Investimentos'!F11*C$7)-('Resumo Investimentos'!F10*C$8) -> 2125358.5 | G23: =('Projeção Receitas'!G20*C$6)-('Resumo Investimentos'!G11*C$7)-('Resumo Investimentos'!G10*C$8) -> 3506448.5
A24: Base - Acumulado | B24: =B23 -> -387287 | C24: =B24+C23 -> -539798.6 | D24: =C24+D23 -> -263895.78 | E24: =D24+E23 -> 708724.03 | F24: =E24+F23 -> 2834082.5 | G24: =F24+G23 -> 6340531.1
A25: Otimista | B25: =-('Resumo Investimentos'!B10*D$8)-('Resumo Investimentos'!B11*D$7) -> -369397.4 | C25: =('Projeção Receitas'!C20*D$6)-('Resumo Investimentos'!C11*D$7)-('Resumo Investimentos'!C10*D$8) -> -51286.02 | D25: =('Projeção Receitas'!D20*D$6)-('Resumo Investimentos'!D11*D$7)-('Resumo Investimentos'!D10*D$8) -> 465597.68 | E25: =('Projeção Receitas'!E20*D$6)-('Resumo Investimentos'!E11*D$7)-('Resumo Investimentos'!E10*D$8) -> 1315212.6 | F25: =('Projeção Receitas'!F20*D$6)-('Resumo Investimentos'!F11*D$7)-('Resumo Investimentos'!F10*D$8) -> 2698732.2 | G25: =('Projeção Receitas'!G20*D$6)-('Resumo Investimentos'!G11*D$7)-('Resumo Investimentos'!G10*D$8) -> 4363455.4
A26: Otimista - Acumulado | B26: =B25 -> -369397.4 | C26: =B26+C25 -> -420683.42 | D26: =C26+D25 -> 44914.259 | E26: =D26+E25 -> 1360126.9 | F26: =E26+F25 -> 4058859.1 | G26: =F26+G25 -> 8422314.5

Sheet Conclusão
A1: Conclusão e Recomendações
A2: Síntese final da decisão e próximos passos
A4: Síntese da Viabilidade
A5: VPL | B5: =Indicadores!B6 -> 3729138.4 | D5: Sinalização automática | E5: =Indicadores!B14 -> VIÁVEL - validar riscos e premissas
A6: TIR | B6: =Indicadores!B7 -> 0.96136055
A7: ROI | B7: =Indicadores!B8 -> 1.9405216
A8: MOIC | B8: =Indicadores!B9 -> 12.746105
A9: Payback | B9: =Indicadores!B10 -> 3
A12: Decisão Final
A13: Recomendação | B13: Aprovar
A15: Justificativa da decisão
A16: O projeto demonstra forte atratividade econômico-financeira com VPL positivo de R$ 2,95M (TMA 12%), TIR de 95%, ROI de 1,52x e Payback estimado em 3 anos, comprovando sustentabilidade operacional e rápida recuperação do capital investido.
A19: Condições para aprovação
A20: 1. Validação dos pilotos/PoCs comerciais no Ano 1 para atingimento da meta inicial de 4 concessionárias ativas. 2. Manutenção do SLA e disponibilidade da infraestrutura AWS e stack SaaS de observabilidade dentro do orçamento projetado. 3. Monitoramento contínuo do churn e retenção dos contratos B2B.
A23: Principais riscos / pontos de atenção
A24: 1. Ciclo de vendas B2B governamental/concessionárias mais longo que o previsto (mitigado por verba GTM dedicada e assessoria comercial). 2. Variação na precisão dos dados climáticos e telemetria (mitigado por múltiplos provedores de dados e validação de features no MVP).
A27: Próximos passos
A28: 1. Finalização do desenvolvimento dos pacotes de trabalho da WBS (MVP BusFlow). 2. Início da prospecção ativa B2B junto às primeiras concessionárias de transporte público de São Paulo. 3. Implantação e homologação do ambiente de observabilidade SaaS e alertas em tempo real.
